Workbook

Sheet MONITORING 
C3: MONITORING REALISASI ANGGARAN | N3: =IF(SUM(K7)<(G7),"REALISASI DIBAWAH TARGET","REALISASI AMAN") -> REALISASI DIBAWAH TARGET
C6: 💰 PAGU ANGGARAN | F6: 📈 RENCANA PENARIKAN DANA | J6: ✅ REALISASI BULAN INI | M6: 📊 PERSENTASE | O6: ⚠ KEKURANGAN / KELEBIHAN
C7: =RAW_SP2D!D4 -> 22677936000 | G7: =RAW_SP2D!E4 -> 2620000000 | K7: =RAW_SP2D!G4 -> 1508164631 | N7: =RAW_SP2D!I4 -> 0.3849278 | Q7: =K7-G7 -> -1111835369
C8: Periode : | D8: =Monitoring_LS!R2 -> Juni 2026
C29: KLUSTER | E29: 51 | G29: 52 | I29: 57
C30: Belanja Pegawai | E30: =Monitoring_LS!E48 -> 1100222526 | G30: =Monitoring_LS!E49 -> 0 | I30: =Monitoring_LS!E49 -> 0
C31: 6301 | E31: 0 | G31: ='Monitoring_UP,KKP,TUP'!H66 -> 45154116 | I31: =Monitoring_LS!I48 -> 26209740
C32: ODHIV | E32: 0 | G32: ='Monitoring_UP,KKP,TUP'!H65 -> 2670000 | I32: =Monitoring_LS!M53 -> 0
C33: KPN | E33: 0 | G33: ='Monitoring_UP,KKP,TUP'!H64 -> 12306000 | I33: =Monitoring_LS!M52 -> 58428000
C34: LANSIA | E34: 0 | G34: ='Monitoring_UP,KKP,TUP'!H63 -> 40400000 | I34: =Monitoring_LS!M51 -> 0
C35: ANAK | E35: 0 | G35: ='Monitoring_UP,KKP,TUP'!H62 -> 40400000 | I35: =Monitoring_LS!M50 -> 58887000
C36: DISABILITAS | E36: 0 | G36: ='Monitoring_UP,KKP,TUP'!H61 -> 28877249 | I36: =Monitoring_LS!M49 -> 58400000
C37: RENTAN | E37: 0 | G37: ='Monitoring_UP,KKP,TUP'!H60 -> 36210000 | I37: =Monitoring_LS!M48 -> 0
C38: TOTAL | E38: =SUM(E30:F37) -> 1100222526 | G38: =SUM(G30:H37) -> 206017365 | I38: =SUM(I30:J37) -> 201924740

Sheet Monitoring_LS
B2: Daftar LS Kontraktual dan Non Kontraktual | R2: Juni 2026
B4: No | C4: Nama Kegiatan | D4: Keterangan | E4: Tanggal BAST | F4: No BAHP | G4: No Invoice | H4: No Kontrak | I4: Tanggal Kontrak | J4: Nilai Tagihan | K4: Tanggal Tagihan Masuk | L4: Deadline Pembayaran | M4: Penyedia | N4: Status Dokumen | O4: Reminder | P4: No. SPM | Q4: SP2D | R4: Tgl. SP2D
B5: 1 | C5: Gaji Juni PNS | D5: Belanja Pegawai | J5: 111195506 | K5: 46174 | L5: =K5+7 -> 46181 | N5: Selesai | O5: =IF(N5="Selesai","AMAN",IF(L5-TODAY()<=3,"SEGERA DIPROSES",IF(TODAY()>L5,"LEWAT DEADLINE","AMAN"))) -> AMAN | P5: 150 | Q5: Sudah Cair | R5: 46174
B6: 2 | C6: Gaji Juni PNS_Yuliana | D6: Belanja Pegawai | J6: 4461622 | K6: 46174 | L6: =K6+7 -> 46181 | N6: Selesai | O6: =IF(N6="Selesai","AMAN",IF(L6-TODAY()<=3,"SEGERA DIPROSES",IF(TODAY()>L6,"LEWAT DEADLINE","AMAN"))) -> AMAN | P6: 151 | Q6: Sudah Cair | R6: 46174
B7: 3 | C7: Gaji Juni PPPK | D7: Belanja Pegawai | J7: 164841870 | K7: 46174 | L7: =K7+7 -> 46181 | N7: Selesai | O7: =IF(N7="Selesai","AMAN",IF(L7-TODAY()<=3,"SEGERA DIPROSES",IF(TODAY()>L7,"LEWAT DEADLINE","AMAN"))) -> AMAN | P7: 152 | Q7: Sudah Cair | R7: 46174
B8: 4 | C8: Gaji 13 PNS | D8: Belanja Pegawai | J8: 114625709 | K8: 46175 | L8: =K8+7 -> 46182 | N8: Selesai | O8: =IF(N8="Selesai","AMAN",IF(L8-TODAY()<=3,"SEGERA DIPROSES",IF(TODAY()>L8,"LEWAT DEADLINE","AMAN"))) -> AMAN | P8: 185 | Q8: Sudah Cair | R8: 46175
B9: 5 | C9: Gaji 13 PNS_Yuliana | D9: Belanja Pegawai | J9: 4617857 | K9: 46175 | L9: =K9+7 -> 46182 | N9: Selesai | O9: =IF(N9="Selesai","AMAN",IF(L9-TODAY()<=3,"SEGERA DIPROSES",IF(TODAY()>L9,"LEWAT DEADLINE","AMAN"))) -> AMAN | P9: 186 | Q9: Sudah Cair | R9: 46175
B10: 6 | C10: Gaji 13 PPPK | D10: Belanja Pegawai | J10: 112567700 | K10: 46175 | L10: =K10+7 -> 46182 | N10: Selesai | O10: =IF(N10="Selesai","AMAN",IF(L10-TODAY()<=3,"SEGERA DIPROSES",IF(TODAY()>L10,"LEWAT DEADLINE","AMAN"))) -> AMAN | P10: 187 | Q10: Sudah Cair | R10: 46175
B11: 7 | C11: Pengadaan Paket Makanan PPKS Residensial tgl 1-30 April 2026 | D11: Disabilitas | E11: 46143 | F11: 131 | G11: 0105-2 | J11: 28950000 | K11: 46171 | L11: =K11+7 -> 46178 | M11: CV. NAHOMBANG RAYA | N11: Selesai | O11: =IF(N11="Selesai","AMAN",IF(L11-TODAY()<=3,"SEGERA DIPROSES",IF(TODAY()>L11,"LEWAT DEADLINE","AMAN"))) -> AMAN | P11: 189 | Q11: Sudah Cair | R11: 46175
B12: 8 | C12: Pengadaan Paket Snack dan Nutrisi PPKS Residensial tgl 1-30 April 2026 | D12: Disabilitas | E12: 46143 | F12: 133 | G12: 0105-4 | J12: 9740000 | K12: 46171 | L12: =K12+7 -> 46178 | M12: CV. NAHOMBANG RAYA | N12: Selesai | O12: =IF(N12="Selesai","AMAN",IF(L12-TODAY()<=3,"SEGERA DIPROSES",IF(TODAY()>L12,"LEWAT DEADLINE","AMAN"))) -> AMAN | P12: 190 | Q12: Sudah Cair | R12: 46175
B13: 9 | C13: Pengadaan Bansos Uang K.Disabilitas di Dairi | D13: Disabilitas | J13: 4210000 | K13: 46175 | L13: =K13+7 -> 46182 | N13: Selesai | O13: =IF(N13="Selesai","AMAN",IF(L13-TODAY()<=3,"SEGERA DIPROSES",IF(TODAY()>L13,"LEWAT DEADLINE","AMAN"))) -> AMAN | P13: 192 | Q13: Sudah Cair | R13: 46177
B14: 10 | C14: Pengadaan Bansos Uang K.Disabilitas di Humbahas | D14: Disabilitas | J14: 2000000 | K14: 46175 | L14: =K14+7 -> 46182 | N14: Selesai | O14: =IF(N14="Selesai","AMAN",IF(L14-TODAY()<=3,"SEGERA DIPROSES",IF(TODAY()>L14,"LEWAT DEADLINE","AMAN"))) -> AMAN | P14: 193 | Q14: Sudah Cair | R14: 46177
B15: 11 | C15: Pengadaan Bansos K.Anak di Kab. Aceh Tamiang | D15: Anak | E15: 46167 | F15: 181 | H15: 180 | I15: 46163 | J15: 58887000 | K15: 46175 | L15: 46175 | M15: CV. NAHOMBANG RAYA | N15: Selesai | O15: =IF(N15="Selesai","AMAN",IF(L15-TODAY()<=3,"SEGERA DIPROSES",IF(TODAY()>L15,"LEWAT DEADLINE","AMAN"))) -> AMAN | P15: 196 | Q15: Sudah Cair | R15: 46178
B16: 12 | C16: Pengadaan Bansos Kewirausahaan K.KPN di Kab. Aceh Tamiang | D16: KPN | E16: 46167 | F16: 183 | H16: 182 | I16: 46163 | J16: 58428000 | K16: 46175 | L16: 46175 | M16: CV. PASTAMA MAROS ALTILENRA | N16: Selesai | O16: =IF(N16="Selesai","AMAN",IF(L16-TODAY()<=3,"SEGERA DIPROSES",IF(TODAY()>L16,"LEWAT DEADLINE","AMAN"))) -> AMAN | P16: 197 | Q16: Sudah Cair | R16: 46178
B17: 13 | C17: Tunkin Mei_PNS | D17: Belanja Pegawai | J17: 127127836 | K17: 46181 | L17: 46182 | N17: Selesai | O17: =IF(N17="Selesai","AMAN",IF(L17-TODAY()<=3,"SEGERA DIPROSES",IF(TODAY()>L17,"LEWAT DEADLINE","AMAN"))) -> AMAN | P17: 199 | Q17: Sudah Cair | R17: 46182
B18: 14 | C18: Tunkin Mei_PNS_Yuliana | D18: Belanja Pegawai | J18: 3305176 | K18: 46181 | L18: 46182 | N18: Selesai | O18: =IF(N18="Selesai","AMAN",IF(L18-TODAY()<=3,"SEGERA DIPROSES",IF(TODAY()>L18,"LEWAT DEADLINE","AMAN"))) -> AMAN | P18: 200 | Q18: Sudah Cair | R18: 46182
B19: 15 | C19: U.Makan Mei_PNS | D19: Belanja Pegawai | J19: 12418000 | K19: 46181 | L19: 46182 | N19: Selesai | O19: =IF(N19="Selesai","AMAN",IF(L19-TODAY()<=3,"SEGERA DIPROSES",IF(TODAY()>L19,"LEWAT DEADLINE","AMAN"))) -> AMAN | P19: 201 | Q19: Sudah Cair | R19: 46182
B20: 16 | C20: U.Makan Mei_PNS_Yuliana | D20: Belanja Pegawai | J20: 592000 | K20: 46181 | L20: 46182 | N20: Selesai | O20: =IF(N20="Selesai","AMAN",IF(L20-TODAY()<=3,"SEGERA DIPROSES",IF(TODAY()>L20,"LEWAT DEADLINE","AMAN"))) -> AMAN | P20: 202 | Q20: Sudah Cair | R20: 46182
B21: 17 | C21: Tunkin 13 PNS | D21: Belanja Pegawai | J21: 134288363 | K21: 46181 | L21: 46182 | N21: Selesai | O21: =IF(N21="Selesai","AMAN",IF(L21-TODAY()<=3,"SEGERA DIPROSES",IF(TODAY()>L21,"LEWAT DEADLINE","AMAN"))) -> AMAN | P21: 203 | Q21: Sudah Cair | R21: 46182
B22: 18 | C22: Tunkin 13 PNS_Yuliana | D22: Belanja Pegawai | J22: 3402266 | K22: 46181 | L22: 46182 | N22: Selesai | O22: =IF(N22="Selesai","AMAN",IF(L22-TODAY()<=3,"SEGERA DIPROSES",IF(TODAY()>L22,"LEWAT DEADLINE","AMAN"))) -> AMAN | P22: 204 | Q22: Sudah Cair | R22: 46182
B23: 19 | C23: Honor Dokter & Psikolog Mei 2026 | D23: Disabilitas | J23: 13500000 | K23: 46181 | L23: 46182 | N23: Selesai | O23: =IF(N23="Selesai","AMAN",IF(L23-TODAY()<=3,"SEGERA DIPROSES",IF(TODAY()>L23,"LEWAT DEADLINE","AMAN"))) -> AMAN | P23: 205 | Q23: Sudah Cair | R23: 46183
B24: 20 | C24: Honor Pengelola Keuangan Mei 2026 | D24: 6301 (52) | J24: 7710000 | K24: 46181 | L24: 46182 | N24: Selesai | O24: =IF(N24="Selesai","AMAN",IF(L24-TODAY()<=3,"SEGERA DIPROSES",IF(TODAY()>L24,"LEWAT DEADLINE","AMAN"))) -> AMAN | P24: 206 | Q24: Sudah Cair | R24: 46183
B25: 21 | C25: Tunkin Mei PPPK | D25: Belanja Pegawai | J25: 166207991 | K25: 46183 | L25: 46183 | N25: Selesai | O25: =IF(N25="Selesai","AMAN",IF(L25-TODAY()<=3,"SEGERA DIPROSES",IF(TODAY()>L25,"LEWAT DEADLINE","AMAN"))) -> AMAN | P25: 208 | Q25: Sudah Cair | R25: 46184
B26: 22 | C26: Tunkin 13 PPPK | D26: Belanja Pegawai | J26: 114108630 | K26: 46183 | L26: 46183 | N26: Selesai | O26: =IF(N26="Selesai","AMAN",IF(L26-TODAY()<=3,"SEGERA DIPROSES",IF(TODAY()>L26,"LEWAT DEADLINE","AMAN"))) -> AMAN | P26: 209 | Q26: Sudah Cair | R26: 46184
B27: 23 | C27: U.Makan Mei PPPK | D27: Belanja Pegawai | J27: 26462000 | K27: 46183 | L27: 46183 | N27: Selesai | O27: =IF(N27="Selesai","AMAN",IF(L27-TODAY()<=3,"SEGERA DIPROSES",IF(TODAY()>L27,"LEWAT DEADLINE","AMAN"))) -> AMAN | P27: 210 | Q27: Sudah Cair | R27: 46184
B28: 24 | C28: Listrik Juni 2026 | D28: 6301 (52) | J28: 18499740 | K28: 46183 | L28: 46183 | N28: Selesai | O28: =IF(N28="Selesai","AMAN",IF(L28-TODAY()<=3,"SEGERA DIPROSES",IF(TODAY()>L28,"LEWAT DEADLINE","AMAN"))) -> AMAN | P28: 214 | Q28: Belum | R28: 46191
O29: =IF(N29="Selesai","AMAN",IF(L29-TODAY()<=3,"SEGERA DIPROSES",IF(TODAY()>L29,"LEWAT DEADLINE","AMAN"))) -> SEGERA DIPROSES
O30: =IF(N30="Selesai","AMAN",IF(L30-TODAY()<=3,"SEGERA DIPROSES",IF(TODAY()>L30,"LEWAT DEADLINE","AMAN"))) -> SEGERA DIPROSES
O31: =IF(N31="Selesai","AMAN",IF(L31-TODAY()<=3,"SEGERA DIPROSES",IF(TODAY()>L31,"LEWAT DEADLINE","AMAN"))) -> SEGERA DIPROSES
O32: =IF(N32="Selesai","AMAN",IF(L32-TODAY()<=3,"SEGERA DIPROSES",IF(TODAY()>L32,"LEWAT DEADLINE","AMAN"))) -> SEGERA DIPROSES
O33: =IF(N33="Selesai","AMAN",IF(L33-TODAY()<=3,"SEGERA DIPROSES",IF(TODAY()>L33,"LEWAT DEADLINE","AMAN"))) -> SEGERA DIPROSES
O34: =IF(N34="Selesai","AMAN",IF(L34-TODAY()<=3,"SEGERA DIPROSES",IF(TODAY()>L34,"LEWAT DEADLINE","AMAN"))) -> SEGERA DIPROSES
O35: =IF(N35="Selesai","AMAN",IF(L35-TODAY()<=3,"SEGERA DIPROSES",IF(TODAY()>L35,"LEWAT DEADLINE","AMAN"))) -> SEGERA DIPROSES
O36: =IF(N36="Selesai","AMAN",IF(L36-TODAY()<=3,"SEGERA DIPROSES",IF(TODAY()>L36,"LEWAT DEADLINE","AMAN"))) -> SEGERA DIPROSES
O37: =IF(N37="Selesai","AMAN",IF(L37-TODAY()<=3,"SEGERA DIPROSES",IF(TODAY()>L37,"LEWAT DEADLINE","AMAN"))) -> SEGERA DIPROSES
O38: =IF(N38="Selesai","AMAN",IF(L38-TODAY()<=3,"SEGERA DIPROSES",IF(TODAY()>L38,"LEWAT DEADLINE","AMAN"))) -> SEGERA DIPROSES
O39: =IF(N39="Selesai","AMAN",IF(L39-TODAY()<=3,"SEGERA DIPROSES",IF(TODAY()>L39,"LEWAT DEADLINE","AMAN"))) -> SEGERA DIPROSES
O40: =IF(N40="Selesai","AMAN",IF(L40-TODAY()<=3,"SEGERA DIPROSES",IF(TODAY()>L40,"LEWAT DEADLINE","AMAN"))) -> SEGERA DIPROSES
... O43: =IF(N43="Selesai","AMAN",IF(L43-TODAY()<=3,"SEGERA DIPROSES",IF(TODAY()>L43,"LEWAT DEADLINE","AMAN"))) -> SEGERA DIPROSES
C45: TOTAL | J45: =SUM(J5:J44) -> 1302147266
...

Sheet Monitoring_UP,KKP,TUP
B2: Transaksi Melalui UP, KKP, dan TUP | M2: Juni 2026
B4: Jenis | C4: No. SPM | D4: Total | E4: No. | F4: Nama Kegiatan | G4: Kluster | H4: Akun | I4: Nilai | J4: Tgl Masuk Tagihan | K4: Deadline Pembayaran | L4: Status Dokumen | M4: Reminder
B5: G-UP | C5: 198 | D5: =SUM(I5:I38) -> 201963865 | E5: 1 | F5: Honor Perawat, Fisioterapi, Pembimbing Senam, dan Spiritual | G5: Anak | H5: =SUMIF(O:O,G5,P:P) -> 6279 | I5: =7200000+3600000+2400000+3300000 -> 16500000 | J5: 46174 | K5: =J5+3 -> 46177 | L5: Selesai | M5: =IF(L5="Selesai","AMAN",IF(K5-TODAY()<=3,"SEGERA DIPROSES",IF(TODAY()>K5,"LEWAT DEADLINE","AMAN"))) -> AMAN | O5: Rentan | P5: 6277
E6: 2 | F6: Transport Petugas Daerah | G6: Rentan | H6: =SUMIF(O:O,G6,P:P) -> 6277 | I6: 13670000 | J6: 46174 | K6: =J6+3 -> 46177 | L6: Selesai | M6: =IF(L5="Selesai","AMAN",IF(K6-TODAY()<=3,"SEGERA DIPROSES",IF(TODAY()>K6,"LEWAT DEADLINE","AMAN"))) -> AMAN | O6: Disabilitas | P6: 6278
E7: 3 | F7: Transport Petugas Daerah | G7: Disabilitas | H7: =SUMIF(O:O,G7,P:P) -> 6278 | I7: 7140000 | J7: 46174 | K7: =J7+3 -> 46177 | L7: Selesai | M7: =IF(L6="Selesai","AMAN",IF(K7-TODAY()<=3,"SEGERA DIPROSES",IF(TODAY()>K7,"LEWAT DEADLINE","AMAN"))) -> AMAN | O7: Anak | P7: 6279
E8: 4 | F8: Transport Petugas Daerah | G8: Anak | H8: =SUMIF(O:O,G8,P:P) -> 6279 | I8: 5250000 | J8: 46174 | K8: =J8+3 -> 46177 | L8: Selesai | M8: =IF(L7="Selesai","AMAN",IF(K8-TODAY()<=3,"SEGERA DIPROSES",IF(TODAY()>K8,"LEWAT DEADLINE","AMAN"))) -> AMAN | O8: Lansia | P8: 6280
E9: 5 | F9: Transport Petugas Daerah | G9: Lansia | H9: =SUMIF(O:O,G9,P:P) -> 6280 | I9: 10630000 | J9: 46174 | K9: =J9+3 -> 46177 | L9: Selesai | M9: =IF(L8="Selesai","AMAN",IF(K9-TODAY()<=3,"SEGERA DIPROSES",IF(TODAY()>K9,"LEWAT DEADLINE","AMAN"))) -> AMAN | O9: KPN | P9: 7992.101
E10: 6 | F10: Transport Petugas Daerah + Uang Harian | G10: KPN | H10: =SUMIF(O:O,G10,P:P) -> 7992.101 | I10: =1920000+150000+170000 -> 2240000 | J10: 46174 | K10: =J10+3 -> 46177 | L10: Selesai | M10: =IF(L9="Selesai","AMAN",IF(K10-TODAY()<=3,"SEGERA DIPROSES",IF(TODAY()>K10,"LEWAT DEADLINE","AMAN"))) -> AMAN | O10: ODHIV | P10: 7992.102
E11: 7 | F11: Sewa Angkutan B.Atensi | G11: Rentan | H11: =SUMIF(O:O,G11,P:P) -> 6277 | I11: 1050000 | J11: 46174 | K11: =J11+3 -> 46177 | L11: Selesai | M11: =IF(L10="Selesai","AMAN",IF(K11-TODAY()<=3,"SEGERA DIPROSES",IF(TODAY()>K11,"LEWAT DEADLINE","AMAN"))) -> AMAN | O11: 6301 (52) | P11: 6301
E12: 8 | F12: Uang Harian + Penginapan + Transport | G12: Rentan | H12: =SUMIF(O:O,G12,P:P) -> 6277 | I12: 19800000 | J12: 46174 | K12: =J12+3 -> 46177 | L12: Selesai | M12: =IF(L11="Selesai","AMAN",IF(K12-TODAY()<=3,"SEGERA DIPROSES",IF(TODAY()>K12,"LEWAT DEADLINE","AMAN"))) -> AMAN
E13: 9 | F13: Transport + Uang Harian | G13: Rentan | H13: =SUMIF(O:O,G13,P:P) -> 6277 | I13: 1690000 | J13: 46174 | K13: =J13+3 -> 46177 | L13: Selesai | M13: =IF(L12="Selesai","AMAN",IF(K13-TODAY()<=3,"SEGERA DIPROSES",IF(TODAY()>K13,"LEWAT DEADLINE","AMAN"))) -> AMAN
E14: 10 | F14: Sewa Angkutan B.Atensi | G14: Disabilitas | H14: =SUMIF(O:O,G14,P:P) -> 6278 | I14: 3500000 | J14: 46174 | K14: =J14+3 -> 46177 | L14: Selesai | M14: =IF(L13="Selesai","AMAN",IF(K14-TODAY()<=3,"SEGERA DIPROSES",IF(TODAY()>K14,"LEWAT DEADLINE","AMAN"))) -> AMAN
E15: 11 | F15: Penginapan + Uang Harian | G15: Disabilitas | H15: =SUMIF(O:O,G15,P:P) -> 6278 | I15: 15361249 | J15: 46174 | K15: =J15+3 -> 46177 | L15: Selesai | M15: =IF(L14="Selesai","AMAN",IF(K15-TODAY()<=3,"SEGERA DIPROSES",IF(TODAY()>K15,"LEWAT DEADLINE","AMAN"))) -> AMAN
E16: 12 | F16: Transport + Uang Harian | G16: Disabilitas | H16: =SUMIF(O:O,G16,P:P) -> 6278 | I16: 940000 | J16: 46174 | K16: =J16+3 -> 46177 | L16: Selesai | M16: =IF(L15="Selesai","AMAN",IF(K16-TODAY()<=3,"SEGERA DIPROSES",IF(TODAY()>K16,"LEWAT DEADLINE","AMAN"))) -> AMAN
E17: 13 | F17: Sewa Angkutan B.Atensi | G17: Anak | H17: =SUMIF(O:O,G17,P:P) -> 6279 | I17: 6000000 | J17: 46174 | K17: =J17+3 -> 46177 | L17: Selesai | M17: =IF(L16="Selesai","AMAN",IF(K17-TODAY()<=3,"SEGERA DIPROSES",IF(TODAY()>K17,"LEWAT DEADLINE","AMAN"))) -> AMAN
E18: 14 | F18: Uang harian | G18: Anak | H18: =SUMIF(O:O,G18,P:P) -> 6279 | I18: 7930000 | J18: 46174 | K18: =J18+3 -> 46177 | L18: Selesai | M18: =IF(L17="Selesai","AMAN",IF(K18-TODAY()<=3,"SEGERA DIPROSES",IF(TODAY()>K18,"LEWAT DEADLINE","AMAN"))) -> AMAN
E19: 15 | F19: Transport + Uang Harian | G19: Anak | H19: =SUMIF(O:O,G19,P:P) -> 6279 | I19: 4720000 | J19: 46174 | K19: =J19+3 -> 46177 | L19: Selesai | M19: =IF(L18="Selesai","AMAN",IF(K19-TODAY()<=3,"SEGERA DIPROSES",IF(TODAY()>K19,"LEWAT DEADLINE","AMAN"))) -> AMAN
E20: 16 | F20: Sewa Angkutan B.Atensi | G20: Lansia | H20: =SUMIF(O:O,G20,P:P) -> 6280 | I20: 20050000 | J20: 46174 | K20: =J20+3 -> 46177 | L20: Selesai | M20: =IF(L19="Selesai","AMAN",IF(K20-TODAY()<=3,"SEGERA DIPROSES",IF(TODAY()>K20,"LEWAT DEADLINE","AMAN"))) -> AMAN
E21: 17 | F21: Uang Harian + Penginapan | G21: Lansia | H21: =SUMIF(O:O,G21,P:P) -> 6280 | I21: 8030000 | J21: 46174 | K21: =J21+3 -> 46177 | L21: Selesai | M21: =IF(L20="Selesai","AMAN",IF(K21-TODAY()<=3,"SEGERA DIPROSES",IF(TODAY()>K21,"LEWAT DEADLINE","AMAN"))) -> AMAN
E22: 18 | F22: Transport + Uang Harian | G22: Lansia | H22: =SUMIF(O:O,G22,P:P) -> 6280 | I22: 1690000 | J22: 46174 | K22: =J22+3 -> 46177 | L22: Selesai | M22: =IF(L21="Selesai","AMAN",IF(K22-TODAY()<=3,"SEGERA DIPROSES",IF(TODAY()>K22,"LEWAT DEADLINE","AMAN"))) -> AMAN
E23: 19 | F23: Sewa Angkutan B.Atensi | G23: KPN | H23: =SUMIF(O:O,G23,P:P) -> 7992.101 | I23: 7550000 | J23: 46174 | K23: =J23+3 -> 46177 | L23: Selesai | M23: =IF(L22="Selesai","AMAN",IF(K23-TODAY()<=3,"SEGERA DIPROSES",IF(TODAY()>K23,"LEWAT DEADLINE","AMAN"))) -> AMAN
... E38: 34 | F38: Pendukung Klinik | G38: 6301 (52) | H38: =SUMIF(O:O,G38,P:P) -> 6301 | I38: 190000 | J38: 46174 | K38: =J38+3 -> 46177 | L38: Selesai | M38: =IF(L37="Selesai","AMAN",IF(K38-TODAY()<=3,"SEGERA DIPROSES",IF(TODAY()>K38,"LEWAT DEADLINE","AMAN"))) -> AMAN
B39: KKP | C39: 207 | D39: =SUM(I39:I41) -> 4053500 | E39: 35 | F39: Penginapan petugas | G39: Disabilitas | H39: =SUMIF(O:O,G39,P:P) -> 6278 | I39: 1936000 | J39: 46174 | K39: =J39+3 -> 46177 | L39: Selesai | M39: =IF(L38="Selesai","AMAN",IF(K39-TODAY()<=3,"SEGERA DIPROSES",IF(TODAY()>K39,"LEWAT DEADLINE","AMAN"))) -> AMAN
E40: 36 | F40: Pengeluaran sehari-hari | G40: 6301 (52) | H40: =SUMIF(O:O,G40,P:P) -> 6301 | I40: 17500 | J40: 46174 | K40: =J40+3 -> 46177 | L40: Selesai | M40: =IF(L39="Selesai","AMAN",IF(K40-TODAY()<=3,"SEGERA DIPROSES",IF(TODAY()>K40,"LEWAT DEADLINE","AMAN"))) -> AMAN
E41: 37 | F41: Biaya Pemeliharaan dan Operasional Kendaraan | G41: 6301 (52) | H41: =SUMIF(O:O,G41,P:P) -> 6301 | I41: 2100000 | J41: 46174 | K41: =J41+3 -> 46177 | L41: Selesai | M41: =IF(L40="Selesai","AMAN",IF(K41-TODAY()<=3,"SEGERA DIPROSES",IF(TODAY()>K41,"LEWAT DEADLINE","AMAN"))) -> AMAN
H42: =SUMIF(O:O,G42,P:P) -> 0
H43: =SUMIF(O:O,G43,P:P) -> 0
H44: =SUMIF(O:O,G44,P:P) -> 0
H45: =SUMIF(O:O,G45,P:P) -> 0
H46: =SUMIF(O:O,G46,P:P) -> 0
H47: =SUMIF(O:O,G47,P:P) -> 0
H48: =SUMIF(O:O,G48,P:P) -> 0
H49: =SUMIF(O:O,G49,P:P) -> 0
H50: =SUMIF(O:O,G50,P:P) -> 0
H51: =SUMIF(O:O,G51,P:P) -> 0
H52: =SUMIF(O:O,G52,P:P) -> 0
H53: =SUMIF(O:O,G53,P:P) -> 0
... H55: =SUMIF(O:O,G55,P:P) -> 0
F57: TOTAL | I57: =SUM(I5:I56) -> 206017365
F59: Rekap | G59: Akun
...

Sheet RAW_SP2D
B2: No. Akun | C2: Uraian | D2: Pagu Revisi | E2: Rencana Penarikan Dana (RPD) | F2: Realisasi TA 2026 | K2: Kekurangan /Kelebihan | L2: Status Realisasi | N2: =TEXT(G4/1000000000,"0.00")&" M" -> 1.51 M
E3: Juni | F3: Lalu | G3: Bulan Ini | H3: Total Realisasi | I3: % | J3: Sisa Anggaran
C4: JUMLAH SELURUHNYA | D4: =X!P9 -> 22677936000 | E4: =E9+E13+E17+E21+E29+E33 -> 2620000000 | F4: =X!V9 -> 7221203315 | G4: =G35 -> 1508164631 | H4: =F4+G4 -> 8729367946 | I4: =I35 -> 0.3849278 | J4: =J35 -> 13948568054 | K4: =G4-E4 -> -1111835369 | L4: =IF(G4>=E4,"LEBIH",IF(G4<E4,"KURANG")) -> KURANG | O4: RPD | P4: Realisasi
B5: DQ Program Perlindungan Sosial | M5: 52 | N5: Belanja Bansos (57) | O5: =E8+E12+E16+E20+E28 -> 870000000 | P5: =G8+G12+G16+G20+G28 -> 175715000 | Q5: =P5-O5 -> -694285000
B6: DQ.6277 | C6: Asistensi Rehabilitasi Sosial Kelompok Rentan | M6: 57 | N6: Belanja Barang Jasa (52) | O6: =E7+E11+E15+E19+E25+E32 -> 450000000 | P6: =G7+G11+G15+G19+G25+G32 -> 232227105 | Q6: =P6-O6 -> -217772895
B7: 52 | C7: Belanja Barang dan Jasa | D7: =X!AP12 -> 372000000 | E7: 33813000 | F7: =X!AP24 -> 67030825 | G7: ='Monitoring_UP,KKP,TUP'!H60 -> 36210000 | H7: =G7+F7 -> 103240825 | I7: =H7/D7 -> 0.2775291 | J7: =D7-H7 -> 268759175 | K7: =G7-E7 -> 2397000 | L7: =IF(G7>=E7,"LEBIH",IF(G7<E7,"KURANG")) -> LEBIH | M7: 51 | N7: Belanja Pegawai (51) | O7: =E31 -> 1300000000 | P7: =G31 -> 1100222526 | Q7: =P7-O7 -> -199777474
B8: 57 | C8: Belanja Bantuan Sosial | D8: =X!AQ12 -> 1032000000 | E8: 120000000 | F8: =X!AQ24 -> 455951900 | G8: =Monitoring_LS!M48 -> 0 | H8: =G8+F8 -> 455951900 | I8: =H8/D8 -> 0.44181386 | J8: =D8-H8 -> 576048100 | K8: =G8-E8 -> -120000000 | L8: =IF(G8>=E8,"LEBIH",IF(G8<E8,"KURANG")) -> KURANG | O8: =SUM(O5:O7) -> 2620000000 | P8: =SUM(P5:P7) -> 1508164631 | Q8: =P8-O8 -> -1111835369
C9: Total | D9: =SUM(D7:D8) -> 1404000000 | E9: =SUM(E7:E8) -> 153813000 | F9: =SUM(F7:F8) -> 522982725 | G9: =SUM(G7:G8) -> 36210000 | H9: =SUM(H7:H8) -> 559192725 | J9: =SUM(J7:J8) -> 844807275 | K9: =G9-E9 -> -117603000 | L9: =IF(G9>=E9,"LEBIH",IF(G9<E9,"KURANG")) -> KURANG
B10: DQ.6278 | C10: Asistensi Rehabilitasi Sosial Penyandang Disabilitas | D10: 0 | F10: 0 | G10: 0 | H10: =G10+F10 -> 0 | J10: =D10-H10 -> 0 | K10: =G10-E10 -> 0
B11: 52 | C11: Belanja Barang dan Jasa | D11: =X!AP13 -> 1426500000 | E11: 91704000 | F11: =X!AP25 -> 313292225 | G11: ='Monitoring_UP,KKP,TUP'!H61 -> 28877249 | H11: =G11+F11 -> 342169474 | I11: =H11/D11 -> 0.23986644 | J11: =D11-H11 -> 1084330526 | K11: =G11-E11 -> -62826751 | L11: =IF(G11>=E11,"LEBIH",IF(G11<E11,"KURANG")) -> KURANG | N11: KLUSTER | O11: RPD | P11: Realisasi | Q11: Selisih | R11: Persentase
B12: 57 | C12: Belanja Bantuan Sosial | D12: =X!AQ13 -> 2140570000 | E12: 120000000 | F12: =X!AQ25 -> 467759400 | G12: =Monitoring_LS!M49 -> 58400000 | H12: =G12+F12 -> 526159400 | I12: =H12/D12 -> 0.24580341 | J12: =D12-H12 -> 1614410600 | K12: =G12-E12 -> -61600000 | L12: =IF(G12>=E12,"LEBIH",IF(G12<E12,"KURANG")) -> KURANG | N12: Rentan | O12: =E9 -> 153813000 | P12: =G9 -> 36210000 | Q12: =P12-O12 -> -117603000 | R12: =P12/O12 -> 0.23541573
C13: Total | D13: =SUM(D11:D12) -> 3567070000 | E13: =SUM(E11:E12) -> 211704000 | F13: =SUM(F11:F12) -> 781051625 | G13: =SUM(G11:G12) -> 87277249 | H13: =SUM(H11:H12) -> 868328874 | J13: =SUM(J11:J12) -> 2698741126 | K13: =G13-E13 -> -124426751 | L13: =IF(G13>=E13,"LEBIH",IF(G13<E13,"KURANG")) -> KURANG | N13: Disabilitas | O13: =E13 -> 211704000 | P13: =G13 -> 87277249 | Q13: =P13-O13 -> -124426751 | R13: =P13/O13 -> 0.41226075
B14: DQ.6279 | C14: Asistensi Rehabilitasi Sosial Anak | D14: 0 | F14: 0 | G14: 0 | H14: =G14+F14 -> 0 | J14: =D14-H14 -> 0 | K14: =G14-E14 -> 0 | N14: Anak | O14: =E17 -> 156772000 | P14: =G17 -> 99287000 | Q14: =P14-O14 -> -57485000 | R14: =P14/O14 -> 0.633321
B15: 52 | C15: Belanja Barang dan Jasa | D15: =X!AP14 -> 480000000 | E15: 36772000 | F15: =X!AP26 -> 74506775 | G15: ='Monitoring_UP,KKP,TUP'!H62 -> 40400000 | H15: =G15+F15 -> 114906775 | I15: =H15/D15 -> 0.23938911 | J15: =D15-H15 -> 365093225 | K15: =G15-E15 -> 3628000 | L15: =IF(G15>=E15,"LEBIH",IF(G15<E15,"KURANG")) -> LEBIH | N15: Lansia | O15: =E21 -> 314304000 | P15: =G21 -> 40400000 | Q15: =P15-O15 -> -273904000 | R15: =P15/O15 -> 0.12853798
B16: 57 | C16: Belanja Bantuan Sosial | D16: =X!AQ14 -> 1320000000 | E16: 120000000 | F16: =X!AQ26 -> 633114400 | G16: =Monitoring_LS!M50 -> 58887000 | H16: =G16+F16 -> 692001400 | I16: =H16/D16 -> 0.52424348 | J16: =D16-H16 -> 627998600 | K16: =G16-E16 -> -61113000 | L16: =IF(G16>=E16,"LEBIH",IF(G16<E16,"KURANG")) -> KURANG | N16: KPN | O16: =E29/2 -> 141402000 | P16: =G29/2 -> 36702000 | Q16: =P16-O16 -> -104700000 | R16: =P16/O16 -> 0.25955786
C17: Total | D17: =SUM(D15:D16) -> 1800000000 | E17: =SUM(E15:E16) -> 156772000 | F17: =SUM(F15:F16) -> 707621175 | G17: =SUM(G15:G16) -> 99287000 | H17: =SUM(H15:H16) -> 806908175 | J17: =SUM(J15:J16) -> 993091825 | K17: =G17-E17 -> -57485000 | L17: =IF(G17>=E17,"LEBIH",IF(G17<E17,"KURANG")) -> KURANG | N17: ODHIV | O17: =E29/2 -> 141402000 | P17: =G29/2 -> 36702000 | Q17: =P17-O17 -> -104700000 | R17: =P17/O17 -> 0.25955786
B18: DQ.6280 | C18: Asistensi Rehabilitasi Sosial Lanjut Usia | D18: 0 | F18: 0 | G18: 0 | H18: =G18+F18 -> 0 | J18: =D18-H18 -> 0 | K18: =G18-E18 -> 0 | N18: 6301 | O18: =E32 -> 200603000 | P18: =G32 -> 71363856 | Q18: =P18-O18 -> -129239144 | R18: =P18/O18 -> 0.3557467
B19: 52 | C19: Belanja Barang dan Jasa | D19: =X!AP15 -> 480000000 | E19: 34304000 | F19: =X!AP27 -> 34655575 | G19: ='Monitoring_UP,KKP,TUP'!H63 -> 40400000 | H19: =G19+F19 -> 75055575 | I19: =H19/D19 -> 0.15636578 | J19: =D19-H19 -> 404944425 | K19: =G19-E19 -> 6096000 | L19: =IF(G19>=E19,"LEBIH",IF(G19<E19,"KURANG")) -> LEBIH | N19: Belanja Pegawai | O19: =E31 -> 1300000000 | P19: =G31 -> 1100222526 | Q19: =P19-O19 -> -199777474 | R19: =P19/O19 -> 0.84632502
B20: 57 | C20: Belanja Bantuan Sosial | D20: =X!AQ15 -> 1320000000 | E20: 280000000 | F20: =X!AQ27 -> 415718600 | G20: =Monitoring_LS!M51 -> 0 | H20: =G20+F20 -> 415718600 | I20: =H20/D20 -> 0.31493833 | J20: =D20-H20 -> 904281400 | K20: =G20-E20 -> -280000000 | L20: =IF(G20>=E20,"LEBIH",IF(G20<E20,"KURANG")) -> KURANG | O20: =SUM(O12:O19) -> 2620000000 | P20: =SUM(P12:P19) -> 1508164631 | Q20: =SUM(Q12:Q19) -> -1111835369 | R20: =P20/O20 -> 0.57563536
C21: Total | D21: =SUM(D19:D20) -> 1800000000 | E21: =SUM(E19:E20) -> 314304000 | F21: =SUM(F19:F20) -> 450374175 | G21: =SUM(G19:G20) -> 40400000 | H21: =SUM(H19:H20) -> 490774175 | J21: =SUM(J19:J20) -> 1309225825 | K21: =G21-E21 -> -273904000 | L21: =IF(G21>=E21,"LEBIH",IF(G21<E21,"KURANG")) -> KURANG
B22: DQ.7992 | C22: Asistensi Rehabilitasi Sosial Korban Penyalahgunaan Napza dan ODHIV | D22: 0 | F22: 0 | G22: 0 | H22: =G22+F22 -> 0 | J22: =D22-H22 -> 0 | K22: =G22-E22 -> 0 | N22: KLUSTER | O22: 51 | P22: 52 | Q22: 57
B23: 52 | C23: Belanja Barang dan Jasa (KPN) | D23: =X!AP16 -> 303000000 | E23: 0 | F23: =X!AP28 -> 26210125 | G23: ='Monitoring_UP,KKP,TUP'!H64 -> 12306000 | H23: =G23+F23 -> 38516125 | I23: =H23/D23 -> 0.12711592 | J23: =D23-H23 -> 264483875 | N23: Rentan | O23: 0 | P23: =G7 -> 36210000 | Q23: =G8 -> 0
B24: 52 | C24: Belanja Barang dan Jasa (ODHIV) | D24: =X!AP17 -> 192000000 | E24: 0 | F24: =X!AP29 -> 19830450 | G24: ='Monitoring_UP,KKP,TUP'!H65 -> 2670000 | H24: =G24+F24 -> 22500450 | I24: =H24/D24 -> 0.11718984 | J24: =D24-H24 -> 169499550 | N24: Disabilitas | O24: 0 | P24: =G11 -> 28877249 | Q24: =G12 -> 58400000
C25: Total 52 | D25: =SUM(D23:D24) -> 495000000 | E25: 52804000 | F25: =SUM(F23:F24) -> 46040575 | G25: =SUM(G23:G24) -> 14976000 | H25: =SUM(H23:H24) -> 61016575 | J25: =SUM(J23:J24) -> 433983425 | K25: =G25-E25 -> -37828000 | L25: =IF(G25>=E25,"LEBIH",IF(G25<E25,"KURANG")) -> KURANG | N25: Anak | O25: 0 | P25: =G15 -> 40400000 | Q25: =G16 -> 58887000
B26: 57 | C26: Belanja Bantuan Sosial (KPN) | D26: =X!AQ16 -> 840000000 | E26: 0 | F26: =X!AQ28 -> 238924400 | G26: =Monitoring_LS!M52 -> 58428000 | H26: =G26+F26 -> 297352400 | I26: =H26/D26 -> 0.35399095 | J26: =D26-H26 -> 542647600 | N26: Lansia | O26: 0 | P26: =G19 -> 40400000 | Q26: =G20 -> 0
B27: 57 | C27: Belanja Bantuan Sosial (ODHIV) | D27: =X!AQ17 -> 528000000 | E27: 0 | F27: =X!AQ29 -> 135337800 | G27: =Monitoring_LS!M53 -> 0 | H27: =G27+F27 -> 135337800 | I27: =H27/D27 -> 0.25632159 | J27: =D27-H27 -> 392662200 | N27: KPN | O27: 0 | P27: =G23 -> 12306000 | Q27: =G26 -> 58428000
C28: Total 57 | D28: =SUM(D26:D27) -> 1368000000 | E28: 230000000 | F28: =SUM(F26:F27) -> 374262200 | G28: =SUM(G26:G27) -> 58428000 | H28: =SUM(H26:H27) -> 432690200 | J28: =SUM(J26:J27) -> 935309800 | K28: =G28-E28 -> -171572000 | L28: =IF(G28>=E28,"LEBIH",IF(G28<E28,"KURANG")) -> KURANG | N28: ODHIV | O28: 0 | P28: =G24 -> 2670000 | Q28: =G27 -> 0
C29: Total 52 + 57 (KPN & ODHIV) | D29: =D25+D28 -> 1863000000 | E29: =E25+E28 -> 282804000 | F29: =F25+F28 -> 420302775 | G29: =G25+G28 -> 73404000 | H29: =H25+H28 -> 493706775 | I29: =I25+I28 -> 0 | J29: =J25+J28 -> 1369293225 | K29: =G29-E29 -> -209400000 | L29: =IF(G29>=E29,"LEBIH",IF(G29<E29,"KURANG")) -> KURANG | N29: 6301 | O29: 0 | P29: =G32 -> 71363856 | Q29: 0
B30: WA.6301 | C30: Pengelolaan Perencanaan, Keuangan, BMN, dan Umum Rehabilitasi Sosial | D30: 0 | F30: 0 | G30: 0 | H30: =G30+F30 -> 0 | J30: =D30-H30 -> 0 | K30: =G30-E30 -> 0 | N30: Belanja Pegawai | O30: =G31 -> 1100222526 | P30: 0
B31: 51 | C31: Belanja Pegawai | D31: =X!AO18 -> 8693395000 | E31: 1300000000 | F31: =X!AO30 -> 3179883826 | G31: =Monitoring_LS!E48 -> 1100222526 | H31: =G31+F31 -> 4280106352 | I31: =H31/D31 -> 0.49234003 | J31: =D31-H31 -> 4413288648 | K31: =G31-E31 -> -199777474 | L31: =IF(G31>=E31,"LEBIH",IF(G31<E31,"KURANG")) -> KURANG | N31: Total | O31: =SUM(O23:O30) -> 1100222526 | P31: =SUM(P23:P30) -> 232227105 | Q31: =SUM(Q23:Q30) -> 175715000 | R31: =SUM(O31:Q31) -> 1508164631
B32: 52 | C32: Belanja Barang dan Jasa | D32: =X!AP18 -> 3550471000 | E32: 200603000 | F32: =X!AP30 -> 1158987014 | G32: ='Monitoring_UP,KKP,TUP'!H66+Monitoring_LS!I48 -> 71363856 | H32: =G32+F32 -> 1230350870 | I32: =H32/D32 -> 0.34653173 | J32: =D32-H32 -> 2320120130 | K32: =G32-E32 -> -129239144 | L32: =IF(G32>=E32,"LEBIH",IF(G32<E32,"KURANG")) -> KURANG
C33: Total | D33: =SUM(D31:D32) -> 12243866000 | E33: =SUM(E31:E32) -> 1500603000 | F33: =SUM(F31:F32) -> 4338870840 | G33: =SUM(G31:G32) -> 1171586382 | H33: =SUM(H31:H32) -> 5510457222 | J33: =SUM(J31:J32) -> 6733408778 | K33: =G33-E33 -> -329016618 | L33: =IF(G33>=E33,"LEBIH",IF(G33<E33,"KURANG")) -> KURANG
C35: TOTAL | D35: =D9+D13+D17+D21+D25+D28+D33 -> 22677936000 | E35: =E9+E13+E17+E21+E25+E28+E33 -> 2620000000 | F35: =F9+F13+F17+F21+F25+F28+F33 -> 7221203315 | G35: =G9+G13+G17+G21+G25+G28+G33 -> 1508164631 | H35: =H9+H13+H17+H21+H25+H28+H33 -> 8729367946 | I35: =H35/D35 -> 0.3849278 | J35: =J9+J13+J17+J21+J25+J28+J33 -> 13948568054 | K35: =K9+K13+K17+K21+K29+K33 -> -1111835369 | L35: =IF(G32>=E32,"LEBIH",IF(G35<E35,"KURANG")) -> KURANG

Sheet X
A1: LAPORAN REALISASI SP2D TA 2026
A2: Per Program; Kegiatan; Output; SubOutput; Komponen; SubKomponen; Akun;
A3: Periode Juni 2026
A4: Kementerian : | N4: 027 | O4: KEMENTERIAN SOSIAL
A5: Unit Organisasi | N5: 04 | O5: DITJEN REHABILITASI SOSIAL
A6: Satuan Kerja : | N6: 690581 | O6: SENTRA "INSYAF" DI MEDAN | AB6: Hal 1 dari | AE6: 8
A7: Uraian | Q7: Pagu Revisi | S7: Lock Pagu | U7: Realisasi TA 2026 | AD7: SISA ANGGARAN
U8: Periode Lalu | W8: Periode Ini | X8: s.d. Periode | AA8: %
A9: JUMLAH SELURUHNYA | P9: 22677936000 | R9: 0 | V9: 7221203315 | W9: 551000264 | X9: 7772203579 | AB9: 0.34272094 | AC9: 14905732421
B10: DQ | D10: Program Perlindungan Sosial | P10: 10434070000 | R10: 0 | V10: 2882332475 | W10: 38690000 | Y10: 2921022475 | AB10: 0.27995044 | AD10: 7513047525 | AM10: Total Pagu
B11: DQ.6277 | I11: Asistensi Rehabilitasi Sosial Kelompok Rentan | P11: 1404000000 | R11: 0 | V11: 522982725 | W11: 0 | Y11: 522982725 | AB11: 0.37249482 | AD11: 881017275 | AO11: 51 | AP11: 52 | AQ11: 57
C12: QAA | G12: Pelayanan Publik kepada masyarakat | P12: 1404000000 | R12: 0 | V12: 522982725 | W12: 0 | Y12: 522982725 | AB12: 0.37249482 | AD12: 881017275 | AM12: 6277 | AP12: =P15+P23+P29 -> 372000000 | AQ12: =P19 -> 1032000000
C13: QAA.101 | K13: Kelompok Rentan yang Mendapatkan Asistensi Rehabilitasi Sosial | P13: 1404000000 | R13: 0 | V13: 522982725 | W13: 0 | Y13: 522982725 | AB13: 0.37249482 | AD13: 881017275 | AM13: 6278 | AP13: =P37+P45+P52+P59 -> 1426500000 | AQ13: =P49+P65 -> 2140570000
E14: 103 | J14: Asesmen Komprehensif | P14: 128970000 | R14: 0 | V14: 19059400 | W14: 0 | Y14: 19059400 | AB14: 0.14778165 | AD14: 109910600 | AM14: 6279 | AP14: =P71+P74+P82+P89 -> 480000000 | AQ14: =P78 -> 1320000000
F15: 103.0A | L15: Pelaksanaan Assesmen | P15: 128970000 | R15: 0 | V15: 19059400 | W15: 0 | Y15: 19059400 | AB15: 0.14778165 | AD15: 109910600 | AM15: 6280 | AP15: =P96+P104+P110 -> 480000000 | AQ15: =P100 -> 1320000000
H16: 524111 | M16: Belanja Perjalanan Dinas Biasa | P16: 78720000 | R16: 0 | V16: 15999400 | W16: 0 | Y16: 15999400 | AB16: 0.20324441 | AD16: 62720600 | AM16: 7992 | AN16: 101 | AP16: =P118+P124+P130 -> 303000000 | AQ16: =P122 -> 840000000
H17: 524113 | M17: Belanja Perjalanan Dinas Dalam Kota | P17: 50250000 | R17: 0 | V17: 3060000 | W17: 0 | Y17: 3060000 | AB17: 0.060895522 | AD17: 47190000 | AN17: 102 | AP17: =P135+P143+P149 -> 192000000 | AQ17: =P140 -> 528000000
E18: 105 | J18: Asistensi Rehabilitasi Sosial (ATENSI) | P18: 1206870000 | R18: 0 | V18: 503923325 | W18: 0 | Y18: 503923325 | AB18: 0.41754566 | AD18: 702946675 | AM18: 6301 | AO18: =P173 -> 8693395000 | AP18: =P156+P159+P198 -> 3550471000
F19: 105.0A | L19: bantuan atensi | P19: 1032000000 | R19: 0 | V19: 455951900 | W19: 0 | Y19: 455951900 | AB19: 0.44181386 | AD19: 576048100 | AO19: =SUM(AO12:AO18) -> 8693395000 | AP19: =SUM(AP12:AP18) -> 6803971000 | AQ19: =SUM(AQ12:AQ18) -> 7180570000
H20: 571111 | M20: Belanja Bantuan Sosial Untuk Rehabilitasi Sosial Dalam Bentuk Uang | P20: 240000000 | R20: 0 | V20: 0 | W20: 0 | Y20: 0 | AB20: 0 | AD20: 240000000 | AO20: =SUM(AO19:AQ19) -> 22677936000
H21: 571112 | M21: Belanja Bantuan Sosial Untuk Rehabilitasi Sosial Dalam Bentuk Barang | P21: 720000000 | R21: 0 | V21: 455951900 | W21: 0 | Y21: 455951900 | AB21: 0.63326653 | AD21: 264048100
H22: 571113 | M22: Belanja Bantuan Sosial Untuk Rehabilitasi Sosial Dalam Bentuk Jasa | P22: 72000000 | R22: 0 | V22: 0 | W22: 0 | Y22: 0 | AB22: 0 | AD22: 72000000 | AM22: Total Periode Lalu
F23: 105.0B | L23: Pelaksanaan atensi | P23: 174870000 | R23: 0 | V23: 47971425 | W23: 0 | Y23: 47971425 | AB23: 0.27432621 | AD23: 126898575 | AO23: 51 | AP23: 52 | AQ23: 57
H24: 521211 | M24: Belanja Bahan | P24: 5800000 | R24: 0 | V24: 4966425 | W24: 0 | Y24: 4966425 | AB24: 0.85628017 | AD24: 833575 | AM24: 6277 | AP24: =V15+V23+V29 -> 67030825 | AQ24: =V19 -> 455951900
H25: 522141 | M25: Belanja Sewa | P25: 40000000 | R25: 0 | V25: 11000000 | W25: 0 | Y25: 11000000 | AB25: 0.275 | AD25: 29000000 | AM25: 6278 | AP25: =V37+V45+V52+V59 -> 313292225 | AQ25: =V49+V65 -> 467759400
H26: 524111 | M26: Belanja Perjalanan Dinas Biasa | P26: 78720000 | R26: 0 | V26: 26215000 | W26: 0 | Y26: 26215000 | AB26: 0.33301575 | AD26: 52505000 | AM26: 6279 | AP26: =V71+V74+V82+V89 -> 74506775 | AQ26: =V78 -> 633114400
H27: 524113 | M27: Belanja Perjalanan Dinas Dalam Kota | P27: 50350000 | R27: 0 | V27: 5790000 | W27: 0 | Y27: 5790000 | AB27: 0.11499503 | AD27: 44560000 | AM27: 6280 | AP27: =V96+V104+V110 -> 34655575 | AQ27: =V100 -> 415718600
E28: 107 | J28: Monev | P28: 68160000 | R28: 0 | V28: 0 | W28: 0 | Y28: 0 | AB28: 0 | AD28: 68160000 | AM28: 7992 | AN28: 101 | AP28: =V118+V124+V130 -> 26210125 | AQ28: =V122 -> 238924400
F29: 107.0A | L29: monitoring evaluasi | P29: 68160000 | R29: 0 | V29: 0 | W29: 0 | Y29: 0 | AB29: 0 | AD29: 68160000 | AN29: 102 | AP29: =V135+V143+V149 -> 19830450 | AQ29: =V140 -> 135337800
H30: 524111 | M30: Belanja Perjalanan Dinas Biasa | P30: 39360000 | R30: 0 | V30: 0 | W30: 0 | Y30: 0 | AB30: 0 | AD30: 39360000 | AM30: 6301 | AO30: =V173 -> 3179883826 | AP30: =V156+V159+V198 -> 1158987014
H31: 524113 | M31: Belanja Perjalanan Dinas Dalam Kota | P31: 28800000 | R31: 0 | V31: 0 | W31: 0 | Y31: 0 | AB31: 0 | AD31: 28800000 | AO31: =SUM(AO24:AO30) -> 3179883826 | AP31: =SUM(AP24:AP30) -> 1694512989 | AQ31: =SUM(AQ24:AQ30) -> 2346806500
B32: DQ.6278 | I32: Asistensi Rehabilitasi Sosial Penyandang Disabilitas | P32: 3567070000 | R32: 0 | V32: 781051625 | W32: 38690000 | Y32: 819741625 | AB32: 0.22980811 | AD32: 2747328375 | AO32: =SUM(AO31:AQ31) -> 7221203315
C33: QAA | G33: Pelayanan Publik kepada masyarakat | P33: 2770500000 | R33: 0 | V33: 521253625 | W33: 38690000 | Y33: 559943625 | AB33: 0.20210923 | AD33: 2210556375
B34: *Lock Pagu adalah jumlah pagu yang sedang dalam proses usulan revisi DIPA atau POK. Lock pagu akan hilang setelah usulan revisi DIPA/POK selesai menjadi DIPA. *SPM Koreksi dalam proses akan masuk sebagai realisasi akhir | AM34: Total Saat ini
C35: QAA.101 | K35: Penyandang Disabilitas yang Mendapatkan Asistensi Rehabilitasi Sosial | P35: 2770500000 | R35: 0 | V35: 521253625 | W35: 38690000 | Y35: 559943625 | AB35: 0.20210923 | AD35: 2210556375 | AO35: 51 | AP35: 52 | AQ35: 57
E36: 005 | J36: Dukungan Penyelenggaraan Tugas dan Fungsi Unit | P36: 1192000000 | R36: 0 | V36: 273743100 | W36: 38690000 | Y36: 312433100 | AB36: 0.26210831 | AD36: 879566900 | AM36: 6277 | AP36: =W15+W23+W29 -> 0 | AQ36: =W19 -> 0
F37: 005.0A | L37: Pendukung atensi residensial | P37: 1192000000 | R37: 0 | V37: 273743100 | W37: 38690000 | Y37: 312433100 | AB37: 0.26210831 | AD37: 879566900 | AM37: 6278 | AP37: =W37+W45+W52+W59 -> 38690000 | AQ37: =W49+W65 -> 0
H38: 521112 | M38: Belanja Pengadaan Bahan Makanan | P38: 56730000 | R38: 0 | V38: 56460000 | W38: 0 | Y38: 56460000 | AB38: 0.99524061 | AD38: 270000 | AM38: 6279 | AP38: =W71+W74+W82+W89 -> 0 | AQ38: =W78 -> 0
H39: 521211 | M39: Belanja Bahan | P39: 182500000 | R39: 0 | V39: 37450000 | W39: 9740000 | Y39: 47190000 | AB39: 0.25857534 | AD39: 135310000 | AM39: 6280 | AP39: =W96+W104+W110 -> 0 | AQ39: =W100 -> 0
H40: 521219 | M40: Belanja Barang Non Operasional Lainnya | P40: 490770000 | R40: 0 | V40: 52990000 | W40: 28950000 | Y40: 81940000 | AB40: 0.16696212 | AD40: 408830000 | AM40: 7992 | AN40: 101 | AP40: =W118+W124+W130 -> 0 | AQ40: =W122 -> 0
...

Sheet Master_Data
B2: JENIS | F2: STATUS DOKUMEN | H2: SP2D | J2: PENYEDIA
B3: Rentan | D3: 6277 | F3: Verifikator | H3: Belum | J3: CV. PASTAMA MAROS ALTILENRA
B4: Disabilitas | D4: 6278 | F4: Revisi | H4: Sudah Cair | J4: CV. NAHOMBANG RAYA
B5: Anak | D5: 6279 | F5: Proses | J5: CV. SADANA SOLUSI UTAMA
B6: Lansia | D6: 6280 | F6: Selesai | J6: CV. MZM KONTRUKSI
B7: KPN | D7: 7992.101
B8: ODHIV | D8: 7992.102
B9: 6301 (52) | D9: 6301
B10: Belanja Pegawai
